Workbook

Sheet 1. Dashboard & Jun-26
A1: SHEET 1 - FUND DASHBOARD & JUNE 2026 RESTATEMENT
A2: Konigstein Affordable Housing Fund (KAHF) — GIPF 99.01% / Konigstein Capital 0.99%. All amounts N$ (NAD). Blue = source figure typed from a named document. Black = formula. Green = link to another tab in this workbook.
A4: A. CAPITAL FROM GIPF — the input side
A5: Total capital allocation approved for investment (fund level) | B5: 446420000 | F5: Fund drawdown register (KAHF_Damask Performance (CHQ) > Drawdowns), row 23 column P.
A6: GIPF capital account at 31 July 2026 | B6: 188072936 | F6: KAHF trial balance as at 28-02-2026, account 5100/020.
A7: GIPF capital account at 28 Feb 2025 (comparative) | B7: 108341357 | F7: Same trial balance, prior-year column. NOTE: a second trial balance in the pack shows N$131,984,039 at the same date — unreconciled.
A8: Konigstein Capital capital account at 28 Feb 2026 | B8: 1518374 | F8: Account 5100/030. GIPF share of paid-in capital = 99.01%.
A9: Movement in GIPF capital, Feb-25 to Jul-26 | B9: =B6-B7 -> 79731579 | F9: Capital called from GIPF during the year.
A10: Capital still callable from GIPF (undrawn) | B10: 2.519026e+08 | F10: Fund drawdown register row 106. Fund total N$254,421,625.91 of which KC N$2,519,025.97.
A11: Management fees charged to the fund, inception to date | B11: 46051257 | F11: Fund drawdown register row 102.
A12: Trust expenses, inception to date | B12: 2748719.5 | F12: Fund drawdown register row 103.
A14: B. DISTRIBUTIONS TO GIPF — the output side
A15: Cash distributions paid out of KAHF to GIPF, inception to date | B15: 0 | F15: NO distribution to GIPF is recorded anywhere in the Fund Model folder. The GIPF capital account shows contributions only, with no drawings. Every "distribution" in this model is a repayment from a project INTO the fund, available for recycling.
A16: Project repayments received into the fund, inception to date | B16: ='2. Project Performance'!D19 -> 2.078e+08 | F16: Sheet 2 portfolio total — ties to the Ledger and to Sheet 4.
A17: of which recycled into new projects or held as fund liquidity | B17: =B16 -> 2.078e+08 | F17: All project repayments have been redeployed or are held in fund liquidity — none has left the fund.
A18: Fund liquidity — Capricorn High Yield Fund at 31 Jul 2026 | B18: 53519718 | F18: CAM investment statement, client 13853366, period 01-31 Jul 2026 (statement dated 11-08-2026).
A19: Fund liquidity — Bank Windhoek current account at 28 Feb 2026 | B19: 6109913.6 | F19: KAHF trial balance 28-02-2026, account 8400/000.
A20: Interest earned on fund liquidity, Jul 2026 | B20: 343457.63 | F20: CAM Interest July 2026 tab, KAHF - Interest Schedule July 2026.
A22: C. BASELINE PERFORMANCE AS AT 30 JUNE 2026
A23: Capital deployed into projects, inception to 30-Jun-26 | B23: =SUMIFS(Ledger!$D$5:$D$107,Ledger!$A$5:$A$107,"<="&DATE(2026,6,30)) -> -3.5238751e+08 | F23: SUMIFS over the Ledger tab, date on or before 30-06-2026.
A24: Distributions received from projects, inception to 30-Jun-26 | B24: =SUMIFS(Ledger!$E$5:$E$107,Ledger!$A$5:$A$107,"<="&DATE(2026,6,30)) -> 2.078e+08
A25: Net capital outstanding at 30-Jun-26 | B25: =B23+B24 -> -1.4458751e+08
A26: Portfolio carrying value / NAV at the June-26 baseline | B26: =SUMIF('2. Project Performance'!B5:B18,"Active*",'2. Project Performance'!I5:I18) -> 1.1769638e+08 | F26: Sum of the carrying values on Sheet 2 — see that tab for the valuation date behind each one.
A27: Cash Available | B27: =+Balance_Sheet_July_2026!C20 -> 67037159
A28: Total value to the fund (distributions + NAV + Cash) | B28: =B24+B26+B27 -> 3.9253354e+08
A29: TVPI on capital deployed at 30-Jun-26 | B29: =B28/-B23 -> 1.1139258
A30: Net gain / (deficit) over capital deployed | B30: =B28+B23 -> 40146028
A31: Interest earned across the loan book, Jan-Jul 2026 | B31: 14897942 | F31: KAHF - Interest Schedule July 2026, "Interest July 2026" tab, total column J.
A33: D. PORTFOLIO SHAPE AT THE REPORTING DATE
A34: Projects in the pack | B34: 14 | F34: Sheet 2 — 10 active, 4 completed.
A35: Completed / fully redeemed projects | B35: 4 | F35: Heavens Ark, NIC Otjomuise Ext 10, Duma Tau, LIH Nkurenkuru Ph 1.
A36: Total planned units across the portfolio | B36: ='3. Delivery Outputs'!B37 -> 6019 | F36: Sheet 3 portfolio total.
A37: Units delivered to date (where the pack records a count) | B37: ='3. Delivery Outputs'!D37 -> 200 | F37: Blanks on Sheet 3 are unrecorded, not zero.
A41: Reading this sheet: The whole of section D is one quarter — Jul to Sep 2026 — and it is dominated by two repayments.
A42: The single most important disclosure on this page is line B (row 16).
A143: D. RESTATEMENT — movements since the June 2026 baseline
A144: Capital deployed after 30-Jun-26 | B144: =SUMIFS(Ledger!$D$5:$D$107,Ledger!$A$5:$A$107,">"&DATE(2026,6,30)) -> -11616720 | F144: Tama Estates Phase 1 N$4,466,720 and PAM Tree notice 089 N$4,150,000, plus C-Breeze / Tama fee offsets.
A145: Distributions received after 30-Jun-26 | B145: =SUMIFS(Ledger!$E$5:$E$107,Ledger!$A$5:$A$107,">"&DATE(2026,6,30)) -> 0 | F145: PAM Tree N$28,390,200 and Turnstone Villas N$14,000,000 — the single largest repayment quarter in the fund's history.
A146: Net movement since the baseline | B146: =B144+B145 -> -11616720
A147: Restated capital deployed, inception to date | B147: ='2. Project Performance'!C19 -> -3.7100423e+08
...

Sheet 2. Project Performance
A1: SHEET 2 — PROJECT-BY-PROJECT PERFORMANCE
A2: Every project in the Fund Model folder. Capital deployed and distributed are SUMIFS over the Ledger tab.
A4: Project | B4: Status | C4: Capital deployed (N$) | D4: Capital distributed (N$) | E4: Net cash position (N$) | F4: Approved deal size / facility (N$) | G4: Total project cost (N$) | H4: Gross development value (N$) | I4: Carrying value / NAV (N$) | J4: Total value (dist. + NAV) | K4: MOIC / TVPI | L4: Updated IRR | M4: IRR basis and source
A5: Aromatic Fresh Notes Investments Pty Ltd - Erf 1470 Khomasdal | B5: Active | C5: =SUMIFS(Ledger!$D$5:$D$109,Ledger!$B$5:$B$109,$A5) -> -95611595 | D5: =SUMIFS(Ledger!$E$5:$E$109,Ledger!$B$5:$B$109,$A5) -> 37033391 | E5: =C5+D5 -> -58578204 | F5: 63500000 | I5: 40105521 | J5: =D5+I5 -> 77138912 | K5: =IFERROR(J5/-C5,"n/a") -> 0.80679453 | L5: 0.0541 | M5: Return Dashboard C8 — realised XIRR. Snapshot 'Expected IRR' on Contract Parameters K103 = 4.0%.
A6: Damask Dunescape Villas | B6: Completed | C6: =SUMIFS(Ledger!$D$5:$D$109,Ledger!$B$5:$B$109,$A6) -> -25551000 | D6: =SUMIFS(Ledger!$E$5:$E$109,Ledger!$B$5:$B$109,$A6) -> 24000000 | E6: =C6+D6 -> -1551000 | F6: 39000000 | I6: 12958884 | J6: =D6+I6 -> 36958884 | K6: =IFERROR(J6/-C6,"n/a") -> 1.446475 | L6: 0.3603 | M6: Historical Ledgers F30 — XIRR incl. NAV N$8,508,452 and PM fees N$7,177,927.
A7: PAM Tree Investment Pty Ltd - Kuisebmund Erf 5758 | B7: Active | C7: =SUMIFS(Ledger!$D$5:$D$109,Ledger!$B$5:$B$109,$A7) -> -45000000 | D7: =SUMIFS(Ledger!$E$5:$E$109,Ledger!$B$5:$B$109,$A7) -> 0 | E7: =C7+D7 -> -45000000 | F7: 45000000 | I7: 35672548 | J7: =D7+I7 -> 35672548 | K7: =IFERROR(J7/-C7,"n/a") -> 0.79272329 | L7: 0.24 | M7: Contract Parameters D31 — reported/projected. Workbook XIRR cell is broken (REF-error / mis-summed -33.5%).
A8: Mossy Wood Notes Investments- Turnstone Villas | B8: Completed | C8: =SUMIFS(Ledger!$D$5:$D$109,Ledger!$B$5:$B$109,$A8) -> -16300000 | D8: =SUMIFS(Ledger!$E$5:$E$109,Ledger!$B$5:$B$109,$A8) -> 0 | E8: =C8+D8 -> -16300000 | F8: 16300000 | I8: 4911828 | J8: =D8+I8 -> 4911828 | K8: =IFERROR(J8/-C8,"n/a") -> 0.30133914 | L8: -0.106 | M8: Return Dashboard D19 — realised XIRR, event-dated, unrealised NAV excluded.
A9: Lithon Developers - Nkurenkuru Ext 2 | B9: Active | C9: =SUMIFS(Ledger!$D$5:$D$109,Ledger!$B$5:$B$109,$A9) -> -5500000 | D9: =SUMIFS(Ledger!$E$5:$E$109,Ledger!$B$5:$B$109,$A9) -> 0 | E9: =C9+D9 -> -5500000 | F9: 5500000 | I9: 1037365.9 | J9: =D9+I9 -> 1037365.9 | K9: =IFERROR(J9/-C9,"n/a") -> 0.18861199 | L9: 0.3011 | M9: Historical Ledgers D111 — IRR incl. terminal NAV. Cash-only realised IRR = 15.76% (D110). The 16.08% on the Return Dashboard is the effective annual rate of the 15% NACM coupon, not an IRR.
A10: Damask- Mondesa Palms | B10: Active | C10: =SUMIFS(Ledger!$D$5:$D$109,Ledger!$B$5:$B$109,$A10) -> -15000000 | D10: =SUMIFS(Ledger!$E$5:$E$109,Ledger!$B$5:$B$109,$A10) -> 0 | E10: =C10+D10 -> -15000000 | F10: 28000000 | G10: 31277884 | H10: 42400000 | I10: 12958884 | J10: =D10+I10 -> 12958884 | K10: =IFERROR(J10/-C10,"n/a") -> 0.8639256 | L10: 0.1894 | M10: Dashboard E9 — realised IRR base case. PROVISIONAL: facility size, rate, first-draw date and unit price are all placeholders.
A11: Blue Mont Pty Ltd The Ridge | B11: Active | C11: =SUMIFS(Ledger!$D$5:$D$109,Ledger!$B$5:$B$109,$A11) -> -20000000 | D11: =SUMIFS(Ledger!$E$5:$E$109,Ledger!$B$5:$B$109,$A11) -> 0 | E11: =C11+D11 -> -20000000 | F11: 30000000 | G11: 27926209 | H11: 38000000 | I11: 13022186 | J11: =D11+I11 -> 13022186 | K11: =IFERROR(J11/-C11,"n/a") -> 0.65110928 | L11: 0.1853 | M11: Dashboard E9 — realised IRR base case.
A12: Mango Cove - Otjomuise Ext 10 | B12: Active | C12: =SUMIFS(Ledger!$D$5:$D$109,Ledger!$B$5:$B$109,$A12) -> -12000000 | D12: =SUMIFS(Ledger!$E$5:$E$109,Ledger!$B$5:$B$109,$A12) -> 0 | E12: =C12+D12 -> -12000000 | F12: 20000000 | I12: 4827160 | J12: =D12+I12 -> 4827160 | K12: =IFERROR(J12/-C12,"n/a") -> 0.40226333 | L12: n/a | M12: No IRR in the pack. Interest schedule prices the loan at 14.0% NACM.
A13: Block 9 - C-Breeze Heights | B13: Active | C13: =SUMIFS(Ledger!$D$5:$D$109,Ledger!$B$5:$B$109,$A13) -> -4389111.1 | D13: =SUMIFS(Ledger!$E$5:$E$109,Ledger!$B$5:$B$109,$A13) -> 0 | E13: =C13+D13 -> -4389111.1 | F13: 5000000 | G13: 26748597 | H13: 31785000 | I13: 4822787 | J13: =D13+I13 -> 4822787 | K13: =IFERROR(J13/-C13,"n/a") -> 1.0988072 | L13: 0.18 | M13: Vert Development Model — 'Equity - Mezzanine' levered IRR (per instruction). Interest schedule: 15.37% base, 18.0% after participation top-up.
A14: Block 9- Tama Estates | B14: Active | C14: =SUMIFS(Ledger!$D$5:$D$109,Ledger!$B$5:$B$109,$A14) -> -4466720.5 | D14: =SUMIFS(Ledger!$E$5:$E$109,Ledger!$B$5:$B$109,$A14) -> 0 | E14: =C14+D14 -> -4466720.5 | F14: 11000000 | G14: 113500309 | H14: 127130303 | I14: 5249926.2 | J14: =D14+I14 -> 5249926.2 | K14: =IFERROR(J14/-C14,"n/a") -> 1.1753425 | L14: 0.208 | M14: Vert Development Model — 'Equity - Investor' levered IRR (per instruction). Interest schedule XIRR on Phase-1 drawn capital = 18.35%.
A15: Duma Tau — Kronlein | B15: Completed | C15: =SUMIFS(Ledger!$D$5:$D$109,Ledger!$B$5:$B$109,$A15) -> -36109399 | D15: =SUMIFS(Ledger!$E$5:$E$109,Ledger!$B$5:$B$109,$A15) -> 42507268 | E15: =C15+D15 -> 6397868.7 | F15: 28000000 | I15: 1197995 | J15: =D15+I15 -> 43705263 | K15: =IFERROR(J15/-C15,"n/a") -> 1.210357 | L15: 0.1289 | M15: Return Dashboard D19 — event-dated XIRR. Supersedes 11.69% and 15.86% previously reported.
A16: LIH- Nkurenkuru Ph 1 | B16: Completed | C16: =SUMIFS(Ledger!$D$5:$D$109,Ledger!$B$5:$B$109,$A16) -> -19076405 | D16: =SUMIFS(Ledger!$E$5:$E$109,Ledger!$B$5:$B$109,$A16) -> 21306076 | E16: =C16+D16 -> 2229670.5 | F16: 18000000 | I16: 1197968.2 | J16: =D16+I16 -> 22504044 | K16: =IFERROR(J16/-C16,"n/a") -> 1.1796795 | L16: 0.1098 | M16: Return Dashboard D19 — XIRR off Net LP cash flow.
A17: NIC - Otjomuise Ext 10 | B17: Completed | C17: =SUMIFS(Ledger!$D$5:$D$109,Ledger!$B$5:$B$109,$A17) -> -7000000 | D17: =SUMIFS(Ledger!$E$5:$E$109,Ledger!$B$5:$B$109,$A17) -> 7353424.5 | E17: =C17+D17 -> 353424.49 | F17: 7000000 | I17: 0 | J17: =D17+I17 -> 7353424.5 | K17: =IFERROR(J17/-C17,"n/a") -> 1.0504892 | L17: 0.1791 | M17: Return Dashboard D19 — realised XIRR, facility fully redeemed 28-Apr-23.
A18: MPG _ Heaven's Ark — Otjomuise Lifestyle Estate | B18: Completed | C18: =SUMIFS(Ledger!$D$5:$D$109,Ledger!$B$5:$B$109,$A18) -> -65000000 | D18: =SUMIFS(Ledger!$E$5:$E$109,Ledger!$B$5:$B$109,$A18) -> 75599843 | E18: =C18+D18 -> 10599843 | F18: 65000000 | I18: 0 | J18: =D18+I18 -> 75599843 | K18: =IFERROR(J18/-C18,"n/a") -> 1.1630745 | L18: 0.1857 | M18: Return Dashboard D19 — XIRR off Net LP cash flow, fully redeemed.
A19: PORTFOLIO TOTAL | C19: =SUM(C5:C18) -> -3.7100423e+08 | D19: =SUM(D5:D18) -> 2.078e+08 | E19: =SUM(E5:E18) -> -1.6320423e+08 | F19: =SUM(F5:F18) -> 381300000 | G19: =SUM(G5:G18) -> 1.99453e+08 | H19: =SUM(H5:H18) -> 239315303 | I19: =SUM(I5:I18) -> 1.3796305e+08 | J19: =SUM(J5:J18) -> 3.4576306e+08 | K19: =IFERROR(J19/-C19,"n/a") -> 0.93196526 | L19: =(L5+L18+L17+L16+L15+L14+L13+L11+L10+L9-L8+L6+L7+L20)/13 -> 0.18674615

Sheet 3. Delivery Outputs
A1: SHEET 3 — DELIVERY OUTPUTS (units built vs planned)
A2: Planned units for the six named projects are hardcoded per instruction (blue). Every other figure is read from the project model named in the last column. Blank = the pack records no figure — do not read blank as zero.
A4: Project | B4: Total planned units | C4: Erven / scope | D4: Units built to date | E4: Units sold / transferred | F4: % complete | G4: Units outstanding | H4: Delivery status | I4: Source in the model pack
A5: A. ACTIVE PROJECTS — planned units hardcoded per instruction
A6: PAM Tree (Erf 5758) | B6: 189 | C6: Erf 5758 Kuisebmund, Walvis Bay — 219 plots on the General Plan | E6: 16 | G6: =IF(ISNUMBER(D6),B6-D6,"") | H6: Phase 1 of 3 under way | I6: Contract Parameters D26 (219 plots), D28 (16 units sold). No units-built count is recorded in the workbook.
A7: C-Breeze Heights | B7: 13 | C7: Erf 1329, CBD Swakopmund — single erf | D7: 0 | E7: 0 | G7: =IF(ISNUMBER(D7),B7-D7,"") -> 13 | H7: Vertical construction Feb-26 to Oct-26 | I7: Vert Development Model p.1 — 13 units, vertical end Oct-2026, transfers end Dec-2026. No completions recorded.
A8: Tama Estates | B8: 87 | C8: Erf 673 Tamariskia — 8 stages | D8: 0 | E8: 0 | G8: =IF(ISNUMBER(D8),B8-D8,"") -> 87 | H8: Horizontal from Apr-26; vertical from Jul-26 | I8: Vert Development Model p.1 — 87 units, vertical start Jul-2026, transfers start Nov-2026.
A9: Mondesa Palms | B9: 134 | C9: 134 units across 3 erven (4420 / 4421 / 4422) | D9: 0 | E9: 0 | F9: 0.15 | G9: =IF(ISNUMBER(D9),B9-D9,"") -> 134 | H9: Erf 4420 (40 units) in construction | I9: Programme F7 — 15% complete at 18-Jun-26; practical completion forecast 09-Feb-27. Model covers Erf 4420 only.
A10: The Ridge — Rocky Crest Ext 4 | B10: 38 | C10: Erf R/E 1502 & Erf 1757, Rocky Crest Ext 4 | D10: 0 | E10: 0 | G10: =IF(ISNUMBER(D10),B10-D10,"") -> 38 | H10: Foundations from Jun-26 | I10: BudgetActual D6 — construction actual N$0 against a N$20.0m budget; practical completion 01-Mar-27.
A11: Mango Cove (Otjomuise Ext 10) | B11: 109 | C11: 109 units across 6 erven | D11: 0 | G11: =IF(ISNUMBER(D11),B11-D11,"") -> 109 | H11: Early drawdown stage | I11: No delivery data in the pack. Unit count taken from the KAHF Projects schedule.
A12: Sub-total — hardcoded plan | B12: =SUM(B6:B11) -> 570 | D12: =SUM(D6:D11) -> 0 | E12: =SUM(E6:E11) -> 16 | G12: =B12-D12 -> 570
A14: B. OTHER PROJECTS IN THE PACK — planned units read from the models
A15: Erf 1470 Khomasdal | B15: 255 | C15: 6 erven; 135 units to be delivered via KAHF (N$27.13m) + FNB (N$20m) | D15: 93 | F15: 0.41 | G15: =IF(ISNUMBER(D15),B15-D15,"") -> 162 | H15: Phase 2 (Erf 7077, 24 units) under way | I15: Contract Parameters C29 (93 constructed), C30 (255 to be constructed), K96 (229 housing units), K102 (41% complete). The three unit counts in this workbook do not agree.
A16: Dunescape Villas (Erf 5159) | B16: 40 | C16: Erf R/E 5159 Ext 15, Swakopmund | D16: 40 | E16: 40 | F16: 1 | G16: =IF(ISNUMBER(D16),B16-D16,"") -> 0 | H16: Complete — all units sold and transferred | I16: Cashflow B48 — 100% complete, all 40 units sold and transferred at 30-Apr-26. Contract Parameters M91 flags only 13 units traceable to a transfer schedule.
A17: Turnstone Villas (Erf 8939) | B17: 17 | C17: Erf 8939 Ext 35, Swakopmund | D17: 17 | E17: 13 | F17: 1 | G17: =IF(ISNUMBER(D17),B17-D17,"") -> 0 | H17: Construction complete 09-Oct-25 | I17: Contract Parameters E97 — construction complete, 13 of 17 transferred, all 17 sold; B112 — 4 sold not yet transferred.
A18: Lithon Nkurenkuru Ext 2 | B18: 37 | C18: Erf 845, Nkurenkuru Ext 2 — Phase 2 | D18: 33 | F18: 0.89 | G18: =IF(ISNUMBER(D18),B18-D18,"") -> 4 | H18: 33 of 37 houses complete at 30-Sep-25 | I18: Cashflow C60/C61/C62 — 37 planned, 33 completed, 89.19% per the fund dashboard.
A19: NIC Otjomuise Ext 10 (Erf 5221) | B19: 17 | C19: Erf 5221, Otjomuise Ext 10, Windhoek | D19: 17 | E19: 17 | F19: 1 | G19: =IF(ISNUMBER(D19),B19-D19,"") -> 0 | H19: Completed — facility redeemed Apr-23 | I19: Contract Parameters D20 — 17 sectional title units. B122 flags units sold as not evidenced.
A20: Sub-total — other projects | B20: =SUM(B15:B19) -> 366 | D20: =SUM(#REF!) -> #REF! | E20: =SUM(#REF!) -> #REF! | G20: =B20-D20 -> #REF!
A21: C. PIPELINE PROJECTS
A22: Ongwediva Town Council | B22: 208 | G22: =IF(ISNUMBER(D22),B22-D22,"") | I22: Kahf Projects Update
A23: Karibib Town Council | B23: 659 | G23: =IF(ISNUMBER(D23),B23-D23,"") | I23: Kahf Projects Update
A24: Goreangab - Waterfront | B24: 815 | G24: =IF(ISNUMBER(D24),B24-D24,"") | I24: Kahf Projects Update
A25: Portion 156 Rundu (Kaisosi Ext 17) | B25: 309 | G25: =IF(ISNUMBER(D25),B25-D25,"") | I25: Kahf Projects Update
A26: Karibi - Nasunga | B26: 84 | G26: =IF(ISNUMBER(D26),B26-D26,"") | I26: Kahf Projects Update
A27: Universitas (Unam) Afrideca | B27: 722 | G27: =IF(ISNUMBER(D27),B27-D27,"")
A28: Auas View | B28: 85
A29: Abigail | B29: 2201
A36: Sub-total — other projects | B36: =SUM(B22:B29) -> 5083 | D36: =SUM(D15:D19) -> 200 | E36: =SUM(E15:E19) -> 70 | G36: =B36-D36 -> 4883
A37: PORTFOLIO TOTAL | B37: =B12+B20+B36 -> 6019 | D37: =D12+D36 -> 200 | E37: =E12+E36 -> 86 | G37: =B37-D37 -> 5819
A39: Blue = hardcoded planned units supplied by the user. Green = figure read from the project model. Black = formula.
A40: Variances against the hardcoded plan, for the record: Mondesa Palms — the model covers Erf 4420 (40 units) only, and the KAHF Projects schedule shows 131, not 134. The Ridge — the KAHF Projects schedule shows 40 units, not 38. PAM Tree, Mango Cove, C-Breeze and Tama agree with the schedule.
A41: Erf 1470 Khomasdal carries three unit counts in one workbook (93 built, 255 to be constructed, 229 housing units, 135 across 6 erven). Treat the delivery number as unaudited until the developer confirms.

Sheet 4. Monthly Cash Flows
A1: SHEET 4 — CONSOLIDATED MONTHLY CASH FLOWS
A2: Live tracking ledger. Every cell is a SUMIFS over the Ledger tab, so adding a dated row on Ledger updates this sheet, Sheet 2 and Sheet 1 automatically. Deployments negative, distributions positive. N$ (NAD).
A4: Month | B4: Fund drawdowns | C4: Fund distributions | D4: Net movement | E4: Cumulative net position | F4: Erf 1470 Khomasdal | G4: Dunescape Villas (Erf 5159) | H4: PAM Tree (Erf 5758) | I4: Turnstone Villas (Erf 8939) | J4: Lithon Nkurenkuru Ext 2 | K4: Mondesa Palms | L4: The Ridge — Rocky Crest Ext 4 | M4: Mango Cove (Otjomuise Ext 10) | N4: C-Breeze Heights | O4: Tama Estates | P4: Duma Tau — Kronlein | Q4: LIH Nkurenkuru Ph 1 | R4: NIC Otjomuise Ext 10 (Erf 5221) | S4: Heavens Ark — Otjomuise
A5: 43040 | B5: =SUMIFS(Ledger!$D$5:$D$109,Ledger!$F$5:$F$109,$A5) -> -47700000 | C5: =SUMIFS(Ledger!$E$5:$E$109,Ledger!$F$5:$F$109,$A5) -> 0 | D5: =B5+C5 -> -47700000 | E5: =D5 -> -47700000 | F5: =SUMIFS(Ledger!$C$5:$C$109,Ledger!$F$5:$F$109,$A5,Ledger!$B$5:$B$109,"Erf 1470 Khomasdal") -> 0 | G5: =SUMIFS(Ledger!$C$5:$C$109,Ledger!$F$5:$F$109,$A5,Ledger!$B$5:$B$109,"Dunescape Villas (Erf 5159)") -> 0 | H5: =SUMIFS(Ledger!$C$5:$C$109,Ledger!$F$5:$F$109,$A5,Ledger!$B$5:$B$109,"PAM Tree (Erf 5758)") -> 0 | I5: =SUMIFS(Ledger!$C$5:$C$109,Ledger!$F$5:$F$109,$A5,Ledger!$B$5:$B$109,"Turnstone Villas (Erf 8939)") -> 0 | J5: =SUMIFS(Ledger!$C$5:$C$109,Ledger!$F$5:$F$109,$A5,Ledger!$B$5:$B$109,"Lithon Nkurenkuru Ext 2") -> 0 | K5: =SUMIFS(Ledger!$C$5:$C$109,Ledger!$F$5:$F$109,$A5,Ledger!$B$5:$B$109,"Mondesa Palms") -> 0 | L5: =SUMIFS(Ledger!$C$5:$C$109,Ledger!$F$5:$F$109,$A5,Ledger!$B$5:$B$109,"The Ridge — Rocky Crest Ext 4") -> 0 | M5: =SUMIFS(Ledger!$C$5:$C$109,Ledger!$F$5:$F$109,$A5,Ledger!$B$5:$B$109,"Mango Cove (Otjomuise Ext 10)") -> 0 | N5: =SUMIFS(Ledger!$C$5:$C$109,Ledger!$F$5:$F$109,$A5,Ledger!$B$5:$B$109,"C-Breeze Heights") -> 0 | O5: =SUMIFS(Ledger!$C$5:$C$109,Ledger!$F$5:$F$109,$A5,Ledger!$B$5:$B$109,"Tama Estates") -> 0 | P5: =SUMIFS(Ledger!$C$5:$C$109,Ledger!$F$5:$F$109,$A5,Ledger!$B$5:$B$109,"Duma Tau — Kronlein") -> 0 | Q5: =SUMIFS(Ledger!$C$5:$C$109,Ledger!$F$5:$F$109,$A5,Ledger!$B$5:$B$109,"LIH Nkurenkuru Ph 1") -> 0 | R5: =SUMIFS(Ledger!$C$5:$C$109,Ledger!$F$5:$F$109,$A5,Ledger!$B$5:$B$109,"NIC Otjomuise Ext 10 (Erf 5221)") -> 0 | S5: =SUMIFS(Ledger!$C$5:$C$109,Ledger!$F$5:$F$109,$A5,Ledger!$B$5:$B$109,"Heavens Ark — Otjomuise") -> 0
A6: 43160 | B6: =SUMIFS(Ledger!$D$5:$D$109,Ledger!$F$5:$F$109,$A6) -> -22000000 | C6: =SUMIFS(Ledger!$E$5:$E$109,Ledger!$F$5:$F$109,$A6) -> 0 | D6: =B6+C6 -> -22000000 | E6: =D6 -> -22000000 | F6: =SUMIFS(Ledger!$C$5:$C$109,Ledger!$F$5:$F$109,$A6,Ledger!$B$5:$B$109,"Erf 1470 Khomasdal") -> 0 | G6: =SUMIFS(Ledger!$C$5:$C$109,Ledger!$F$5:$F$109,$A6,Ledger!$B$5:$B$109,"Dunescape Villas (Erf 5159)") -> 0 | H6: =SUMIFS(Ledger!$C$5:$C$109,Ledger!$F$5:$F$109,$A6,Ledger!$B$5:$B$109,"PAM Tree (Erf 5758)") -> 0 | I6: =SUMIFS(Ledger!$C$5:$C$109,Ledger!$F$5:$F$109,$A6,Ledger!$B$5:$B$109,"Turnstone Villas (Erf 8939)") -> 0 | J6: =SUMIFS(Ledger!$C$5:$C$109,Ledger!$F$5:$F$109,$A6,Ledger!$B$5:$B$109,"Lithon Nkurenkuru Ext 2") -> 0 | K6: =SUMIFS(Ledger!$C$5:$C$109,Ledger!$F$5:$F$109,$A6,Ledger!$B$5:$B$109,"Mondesa Palms") -> 0 | L6: =SUMIFS(Ledger!$C$5:$C$109,Ledger!$F$5:$F$109,$A6,Ledger!$B$5:$B$109,"The Ridge — Rocky Crest Ext 4") -> 0 | M6: =SUMIFS(Ledger!$C$5:$C$109,Ledger!$F$5:$F$109,$A6,Ledger!$B$5:$B$109,"Mango Cove (Otjomuise Ext 10)") -> 0 | N6: =SUMIFS(Ledger!$C$5:$C$109,Ledger!$F$5:$F$109,$A6,Ledger!$B$5:$B$109,"C-Breeze Heights") -> 0 | O6: =SUMIFS(Ledger!$C$5:$C$109,Ledger!$F$5:$F$109,$A6,Ledger!$B$5:$B$109,"Tama Estates") -> 0 | P6: =SUMIFS(Ledger!$C$5:$C$109,Ledger!$F$5:$F$109,$A6,Ledger!$B$5:$B$109,"Duma Tau — Kronlein") -> -22000000 | Q6: =SUMIFS(Ledger!$C$5:$C$109,Ledger!$F$5:$F$109,$A6,Ledger!$B$5:$B$109,"LIH Nkurenkuru Ph 1") -> 0 | R6: =SUMIFS(Ledger!$C$5:$C$109,Ledger!$F$5:$F$109,$A6,Ledger!$B$5:$B$109,"NIC Otjomuise Ext 10 (Erf 5221)") -> 0 | S6: =SUMIFS(Ledger!$C$5:$C$109,Ledger!$F$5:$F$109,$A6,Ledger!$B$5:$B$109,"Heavens Ark — Otjomuise") -> 0
A7: 43191 | B7: =SUMIFS(Ledger!$D$5:$D$109,Ledger!$F$5:$F$109,$A7) -> -10000000 | C7: =SUMIFS(Ledger!$E$5:$E$109,Ledger!$F$5:$F$109,$A7) -> 0 | D7: =B7+C7 -> -10000000 | E7: =D7 -> -10000000 | F7: =SUMIFS(Ledger!$C$5:$C$109,Ledger!$F$5:$F$109,$A7,Ledger!$B$5:$B$109,"Erf 1470 Khomasdal") -> 0 | G7: =SUMIFS(Ledger!$C$5:$C$109,Ledger!$F$5:$F$109,$A7,Ledger!$B$5:$B$109,"Dunescape Villas (Erf 5159)") -> 0 | H7: =SUMIFS(Ledger!$C$5:$C$109,Ledger!$F$5:$F$109,$A7,Ledger!$B$5:$B$109,"PAM Tree (Erf 5758)") -> 0 | I7: =SUMIFS(Ledger!$C$5:$C$109,Ledger!$F$5:$F$109,$A7,Ledger!$B$5:$B$109,"Turnstone Villas (Erf 8939)") -> 0 | J7: =SUMIFS(Ledger!$C$5:$C$109,Ledger!$F$5:$F$109,$A7,Ledger!$B$5:$B$109,"Lithon Nkurenkuru Ext 2") -> 0 | K7: =SUMIFS(Ledger!$C$5:$C$109,Ledger!$F$5:$F$109,$A7,Ledger!$B$5:$B$109,"Mondesa Palms") -> 0 | L7: =SUMIFS(Ledger!$C$5:$C$109,Ledger!$F$5:$F$109,$A7,Ledger!$B$5:$B$109,"The Ridge — Rocky Crest Ext 4") -> 0 | M7: =SUMIFS(Ledger!$C$5:$C$109,Ledger!$F$5:$F$109,$A7,Ledger!$B$5:$B$109,"Mango Cove (Otjomuise Ext 10)") -> 0 | N7: =SUMIFS(Ledger!$C$5:$C$109,Ledger!$F$5:$F$109,$A7,Ledger!$B$5:$B$109,"C-Breeze Heights") -> 0 | O7: =SUMIFS(Ledger!$C$5:$C$109,Ledger!$F$5:$F$109,$A7,Ledger!$B$5:$B$109,"Tama Estates") -> 0 | P7: =SUMIFS(Ledger!$C$5:$C$109,Ledger!$F$5:$F$109,$A7,Ledger!$B$5:$B$109,"Duma Tau — Kronlein") -> 0 | Q7: =SUMIFS(Ledger!$C$5:$C$109,Ledger!$F$5:$F$109,$A7,Ledger!$B$5:$B$109,"LIH Nkurenkuru Ph 1") -> 0 | R7: =SUMIFS(Ledger!$C$5:$C$109,Ledger!$F$5:$F$109,$A7,Ledger!$B$5:$B$109,"NIC Otjomuise Ext 10 (Erf 5221)") -> 0 | S7: =SUMIFS(Ledger!$C$5:$C$109,Ledger!$F$5:$F$109,$A7,Ledger!$B$5:$B$109,"Heavens Ark — Otjomuise") -> 0
A8: 43252 | B8: =SUMIFS(Ledger!$D$5:$D$109,Ledger!$F$5:$F$109,$A8) -> -700000 | C8: =SUMIFS(Ledger!$E$5:$E$109,Ledger!$F$5:$F$109,$A8) -> 0 | D8: =B8+C8 -> -700000 | E8: =D8 -> -700000 | F8: =SUMIFS(Ledger!$C$5:$C$109,Ledger!$F$5:$F$109,$A8,Ledger!$B$5:$B$109,"Erf 1470 Khomasdal") -> 0 | G8: =SUMIFS(Ledger!$C$5:$C$109,Ledger!$F$5:$F$109,$A8,Ledger!$B$5:$B$109,"Dunescape Villas (Erf 5159)") -> 0 | H8: =SUMIFS(Ledger!$C$5:$C$109,Ledger!$F$5:$F$109,$A8,Ledger!$B$5:$B$109,"PAM Tree (Erf 5758)") -> 0 | I8: =SUMIFS(Ledger!$C$5:$C$109,Ledger!$F$5:$F$109,$A8,Ledger!$B$5:$B$109,"Turnstone Villas (Erf 8939)") -> 0 | J8: =SUMIFS(Ledger!$C$5:$C$109,Ledger!$F$5:$F$109,$A8,Ledger!$B$5:$B$109,"Lithon Nkurenkuru Ext 2") -> 0 | K8: =SUMIFS(Ledger!$C$5:$C$109,Ledger!$F$5:$F$109,$A8,Ledger!$B$5:$B$109,"Mondesa Palms") -> 0 | L8: =SUMIFS(Ledger!$C$5:$C$109,Ledger!$F$5:$F$109,$A8,Ledger!$B$5:$B$109,"The Ridge — Rocky Crest Ext 4") -> 0 | M8: =SUMIFS(Ledger!$C$5:$C$109,Ledger!$F$5:$F$109,$A8,Ledger!$B$5:$B$109,"Mango Cove (Otjomuise Ext 10)") -> 0 | N8: =SUMIFS(Ledger!$C$5:$C$109,Ledger!$F$5:$F$109,$A8,Ledger!$B$5:$B$109,"C-Breeze Heights") -> 0 | O8: =SUMIFS(Ledger!$C$5:$C$109,Ledger!$F$5:$F$109,$A8,Ledger!$B$5:$B$109,"Tama Estates") -> 0 | P8: =SUMIFS(Ledger!$C$5:$C$109,Ledger!$F$5:$F$109,$A8,Ledger!$B$5:$B$109,"Duma Tau — Kronlein") -> 0 | Q8: =SUMIFS(Ledger!$C$5:$C$109,Ledger!$F$5:$F$109,$A8,Ledger!$B$5:$B$109,"LIH Nkurenkuru Ph 1") -> 0 | R8: =SUMIFS(Ledger!$C$5:$C$109,Ledger!$F$5:$F$109,$A8,Ledger!$B$5:$B$109,"NIC Otjomuise Ext 10 (Erf 5221)") -> 0 | S8: =SUMIFS(Ledger!$C$5:$C$109,Ledger!$F$5:$F$109,$A8,Ledger!$B$5:$B$109,"Heavens Ark — Otjomuise") -> 0
A9: 43282 | B9: =SUMIFS(Ledger!$D$5:$D$109,Ledger!$F$5:$F$109,$A9) -> -4300000 | C9: =SUMIFS(Ledger!$E$5:$E$109,Ledger!$F$5:$F$109,$A9) -> 0 | D9: =B9+C9 -> -4300000 | E9: =D9 -> -4300000 | F9: =SUMIFS(Ledger!$C$5:$C$109,Ledger!$F$5:$F$109,$A9,Ledger!$B$5:$B$109,"Erf 1470 Khomasdal") -> 0 | G9: =SUMIFS(Ledger!$C$5:$C$109,Ledger!$F$5:$F$109,$A9,Ledger!$B$5:$B$109,"Dunescape Villas (Erf 5159)") -> 0 | H9: =SUMIFS(Ledger!$C$5:$C$109,Ledger!$F$5:$F$109,$A9,Ledger!$B$5:$B$109,"PAM Tree (Erf 5758)") -> 0 | I9: =SUMIFS(Ledger!$C$5:$C$109,Ledger!$F$5:$F$109,$A9,Ledger!$B$5:$B$109,"Turnstone Villas (Erf 8939)") -> 0 | J9: =SUMIFS(Ledger!$C$5:$C$109,Ledger!$F$5:$F$109,$A9,Ledger!$B$5:$B$109,"Lithon Nkurenkuru Ext 2") -> 0 | K9: =SUMIFS(Ledger!$C$5:$C$109,Ledger!$F$5:$F$109,$A9,Ledger!$B$5:$B$109,"Mondesa Palms") -> 0 | L9: =SUMIFS(Ledger!$C$5:$C$109,Ledger!$F$5:$F$109,$A9,Ledger!$B$5:$B$109,"The Ridge — Rocky Crest Ext 4") -> 0 | M9: =SUMIFS(Ledger!$C$5:$C$109,Ledger!$F$5:$F$109,$A9,Ledger!$B$5:$B$109,"Mango Cove (Otjomuise Ext 10)") -> 0 | N9: =SUMIFS(Ledger!$C$5:$C$109,Ledger!$F$5:$F$109,$A9,Ledger!$B$5:$B$109,"C-Breeze Heights") -> 0 | O9: =SUMIFS(Ledger!$C$5:$C$109,Ledger!$F$5:$F$109,$A9,Ledger!$B$5:$B$109,"Tama Estates") -> 0 | P9: =SUMIFS(Ledger!$C$5:$C$109,Ledger!$F$5:$F$109,$A9,Ledger!$B$5:$B$109,"Duma Tau — Kronlein") -> 0 | Q9: =SUMIFS(Ledger!$C$5:$C$109,Ledger!$F$5:$F$109,$A9,Ledger!$B$5:$B$109,"LIH Nkurenkuru Ph 1") -> 0 | R9: =SUMIFS(Ledger!$C$5:$C$109,Ledger!$F$5:$F$109,$A9,Ledger!$B$5:$B$109,"NIC Otjomuise Ext 10 (Erf 5221)") -> 0 | S9: =SUMIFS(Ledger!$C$5:$C$109,Ledger!$F$5:$F$109,$A9,Ledger!$B$5:$B$109,"Heavens Ark — Otjomuise") -> 0
A10: 43313 | B10: =SUMIFS(Ledger!$D$5:$D$109,Ledger!$F$5:$F$109,$A10) -> -11000000 | C10: =SUMIFS(Ledger!$E$5:$E$109,Ledger!$F$5:$F$109,$A10) -> 0 | D10: =B10+C10 -> -11000000 | E10: =D10 -> -11000000 | F10: =SUMIFS(Ledger!$C$5:$C$109,Ledger!$F$5:$F$109,$A10,Ledger!$B$5:$B$109,"Erf 1470 Khomasdal") -> 0 | G10: =SUMIFS(Ledger!$C$5:$C$109,Ledger!$F$5:$F$109,$A10,Ledger!$B$5:$B$109,"Dunescape Villas (Erf 5159)") -> 0 | H10: =SUMIFS(Ledger!$C$5:$C$109,Ledger!$F$5:$F$109,$A10,Ledger!$B$5:$B$109,"PAM Tree (Erf 5758)") -> 0 | I10: =SUMIFS(Ledger!$C$5:$C$109,Ledger!$F$5:$F$109,$A10,Ledger!$B$5:$B$109,"Turnstone Villas (Erf 8939)") -> 0 | J10: =SUMIFS(Ledger!$C$5:$C$109,Ledger!$F$5:$F$109,$A10,Ledger!$B$5:$B$109,"Lithon Nkurenkuru Ext 2") -> 0 | K10: =SUMIFS(Ledger!$C$5:$C$109,Ledger!$F$5:$F$109,$A10,Ledger!$B$5:$B$109,"Mondesa Palms") -> 0 | L10: =SUMIFS(Ledger!$C$5:$C$109,Ledger!$F$5:$F$109,$A10,Ledger!$B$5:$B$109,"The Ridge — Rocky Crest Ext 4") -> 0 | M10: =SUMIFS(Ledger!$C$5:$C$109,Ledger!$F$5:$F$109,$A10,Ledger!$B$5:$B$109,"Mango Cove (Otjomuise Ext 10)") -> 0 | N10: =SUMIFS(Ledger!$C$5:$C$109,Ledger!$F$5:$F$109,$A10,Ledger!$B$5:$B$109,"C-Breeze Heights") -> 0 | O10: =SUMIFS(Ledger!$C$5:$C$109,Ledger!$F$5:$F$109,$A10,Ledger!$B$5:$B$109,"Tama Estates") -> 0 | P10: =SUMIFS(Ledger!$C$5:$C$109,Ledger!$F$5:$F$109,$A10,Ledger!$B$5:$B$109,"Duma Tau — Kronlein") -> -6000000 | Q10: =SUMIFS(Ledger!$C$5:$C$109,Ledger!$F$5:$F$109,$A10,Ledger!$B$5:$B$109,"LIH Nkurenkuru Ph 1") -> 0 | R10: =SUMIFS(Ledger!$C$5:$C$109,Ledger!$F$5:$F$109,$A10,Ledger!$B$5:$B$109,"NIC Otjomuise Ext 10 (Erf 5221)") -> 0 | S10: =SUMIFS(Ledger!$C$5:$C$109,Ledger!$F$5:$F$109,$A10,Ledger!$B$5:$B$109,"Heavens Ark — Otjomuise") -> 0
A11: 43344 | B11: =SUMIFS(Ledger!$D$5:$D$109,Ledger!$F$5:$F$109,$A11) -> -2500000 | C11: =SUMIFS(Ledger!$E$5:$E$109,Ledger!$F$5:$F$109,$A11) -> 1302000 | D11: =B11+C11 -> -1198000 | E11: =D11 -> -1198000 | F11: =SUMIFS(Ledger!$C$5:$C$109,Ledger!$F$5:$F$109,$A11,Ledger!$B$5:$B$109,"Erf 1470 Khomasdal") -> 0 | G11: =SUMIFS(Ledger!$C$5:$C$109,Ledger!$F$5:$F$109,$A11,Ledger!$B$5:$B$109,"Dunescape Villas (Erf 5159)") -> 0 | H11: =SUMIFS(Ledger!$C$5:$C$109,Ledger!$F$5:$F$109,$A11,Ledger!$B$5:$B$109,"PAM Tree (Erf 5758)") -> 0 | I11: =SUMIFS(Ledger!$C$5:$C$109,Ledger!$F$5:$F$109,$A11,Ledger!$B$5:$B$109,"Turnstone Villas (Erf 8939)") -> 0 | J11: =SUMIFS(Ledger!$C$5:$C$109,Ledger!$F$5:$F$109,$A11,Ledger!$B$5:$B$109,"Lithon Nkurenkuru Ext 2") -> 0 | K11: =SUMIFS(Ledger!$C$5:$C$109,Ledger!$F$5:$F$109,$A11,Ledger!$B$5:$B$109,"Mondesa Palms") -> 0 | L11: =SUMIFS(Ledger!$C$5:$C$109,Ledger!$F$5:$F$109,$A11,Ledger!$B$5:$B$109,"The Ridge — Rocky Crest Ext 4") -> 0 | M11: =SUMIFS(Ledger!$C$5:$C$109,Ledger!$F$5:$F$109,$A11,Ledger!$B$5:$B$109,"Mango Cove (Otjomuise Ext 10)") -> 0 | N11: =SUMIFS(Ledger!$C$5:$C$109,Ledger!$F$5:$F$109,$A11,Ledger!$B$5:$B$109,"C-Breeze Heights") -> 0 | O11: =SUMIFS(Ledger!$C$5:$C$109,Ledger!$F$5:$F$109,$A11,Ledger!$B$5:$B$109,"Tama Estates") -> 0 | P11: =SUMIFS(Ledger!$C$5:$C$109,Ledger!$F$5:$F$109,$A11,Ledger!$B$5:$B$109,"Duma Tau — Kronlein") -> 1302000 | Q11: =SUMIFS(Ledger!$C$5:$C$109,Ledger!$F$5:$F$109,$A11,Ledger!$B$5:$B$109,"LIH Nkurenkuru Ph 1") -> 0 | R11: =SUMIFS(Ledger!$C$5:$C$109,Ledger!$F$5:$F$109,$A11,Ledger!$B$5:$B$109,"NIC Otjomuise Ext 10 (Erf 5221)") -> 0 | S11: =SUMIFS(Ledger!$C$5:$C$109,Ledger!$F$5:$F$109,$A11,Ledger!$B$5:$B$109,"Heavens Ark — Otjomuise") -> 0
A12: 43374 | B12: =SUMIFS(Ledger!$D$5:$D$109,Ledger!$F$5:$F$109,$A12) -> -10000000 | C12: =SUMIFS(Ledger!$E$5:$E$109,Ledger!$F$5:$F$109,$A12) -> 0 | D12: =B12+C12 -> -10000000 | E12: =D12 -> -10000000 | F12: =SUMIFS(Ledger!$C$5:$C$109,Ledger!$F$5:$F$109,$A12,Ledger!$B$5:$B$109,"Erf 1470 Khomasdal") -> 0 | G12: =SUMIFS(Ledger!$C$5:$C$109,Ledger!$F$5:$F$109,$A12,Ledger!$B$5:$B$109,"Dunescape Villas (Erf 5159)") -> 0 | H12: =SUMIFS(Ledger!$C$5:$C$109,Ledger!$F$5:$F$109,$A12,Ledger!$B$5:$B$109,"PAM Tree (Erf 5758)") -> 0 | I12: =SUMIFS(Ledger!$C$5:$C$109,Ledger!$F$5:$F$109,$A12,Ledger!$B$5:$B$109,"Turnstone Villas (Erf 8939)") -> 0 | J12: =SUMIFS(Ledger!$C$5:$C$109,Ledger!$F$5:$F$109,$A12,Ledger!$B$5:$B$109,"Lithon Nkurenkuru Ext 2") -> 0 | K12: =SUMIFS(Ledger!$C$5:$C$109,Ledger!$F$5:$F$109,$A12,Ledger!$B$5:$B$109,"Mondesa Palms") -> 0 | L12: =SUMIFS(Ledger!$C$5:$C$109,Ledger!$F$5:$F$109,$A12,Ledger!$B$5:$B$109,"The Ridge — Rocky Crest Ext 4") -> 0 | M12: =SUMIFS(Ledger!$C$5:$C$109,Ledger!$F$5:$F$109,$A12,Ledger!$B$5:$B$109,"Mango Cove (Otjomuise Ext 10)") -> 0 | N12: =SUMIFS(Ledger!$C$5:$C$109,Ledger!$F$5:$F$109,$A12,Ledger!$B$5:$B$109,"C-Breeze Heights") -> 0 | O12: =SUMIFS(Ledger!$C$5:$C$109,Ledger!$F$5:$F$109,$A12,Ledger!$B$5:$B$109,"Tama Estates") -> 0 | P12: =SUMIFS(Ledger!$C$5:$C$109,Ledger!$F$5:$F$109,$A12,Ledger!$B$5:$B$109,"Duma Tau — Kronlein") -> 0 | Q12: =SUMIFS(Ledger!$C$5:$C$109,Ledger!$F$5:$F$109,$A12,Ledger!$B$5:$B$109,"LIH Nkurenkuru Ph 1") -> 0 | R12: =SUMIFS(Ledger!$C$5:$C$109,Ledger!$F$5:$F$109,$A12,Ledger!$B$5:$B$109,"NIC Otjomuise Ext 10 (Erf 5221)") -> 0 | S12: =SUMIFS(Ledger!$C$5:$C$109,Ledger!$F$5:$F$109,$A12,Ledger!$B$5:$B$109,"Heavens Ark — Otjomuise") -> 0
A13: 43405 | B13: =SUMIFS(Ledger!$D$5:$D$109,Ledger!$F$5:$F$109,$A13) -> -11600000 | C13: =SUMIFS(Ledger!$E$5:$E$109,Ledger!$F$5:$F$109,$A13) -> 0 | D13: =B13+C13 -> -11600000 | E13: =D13 -> -11600000 | F13: =SUMIFS(Ledger!$C$5:$C$109,Ledger!$F$5:$F$109,$A13,Ledger!$B$5:$B$109,"Erf 1470 Khomasdal") -> 0 | G13: =SUMIFS(Ledger!$C$5:$C$109,Ledger!$F$5:$F$109,$A13,Ledger!$B$5:$B$109,"Dunescape Villas (Erf 5159)") -> 0 | H13: =SUMIFS(Ledger!$C$5:$C$109,Ledger!$F$5:$F$109,$A13,Ledger!$B$5:$B$109,"PAM Tree (Erf 5758)") -> 0 | I13: =SUMIFS(Ledger!$C$5:$C$109,Ledger!$F$5:$F$109,$A13,Ledger!$B$5:$B$109,"Turnstone Villas (Erf 8939)") -> 0 | J13: =SUMIFS(Ledger!$C$5:$C$109,Ledger!$F$5:$F$109,$A13,Ledger!$B$5:$B$109,"Lithon Nkurenkuru Ext 2") -> 0 | K13: =SUMIFS(Ledger!$C$5:$C$109,Ledger!$F$5:$F$109,$A13,Ledger!$B$5:$B$109,"Mondesa Palms") -> 0 | L13: =SUMIFS(Ledger!$C$5:$C$109,Ledger!$F$5:$F$109,$A13,Ledger!$B$5:$B$109,"The Ridge — Rocky Crest Ext 4") -> 0 | M13: =SUMIFS(Ledger!$C$5:$C$109,Ledger!$F$5:$F$109,$A13,Ledger!$B$5:$B$109,"Mango Cove (Otjomuise Ext 10)") -> 0 | N13: =SUMIFS(Ledger!$C$5:$C$109,Ledger!$F$5:$F$109,$A13,Ledger!$B$5:$B$109,"C-Breeze Heights") -> 0 | O13: =SUMIFS(Ledger!$C$5:$C$109,Ledger!$F$5:$F$109,$A13,Ledger!$B$5:$B$109,"Tama Estates") -> 0 | P13: =SUMIFS(Ledger!$C$5:$C$109,Ledger!$F$5:$F$109,$A13,Ledger!$B$5:$B$109,"Duma Tau — Kronlein") -> 0 | Q13: =SUMIFS(Ledger!$C$5:$C$109,Ledger!$F$5:$F$109,$A13,Ledger!$B$5:$B$109,"LIH Nkurenkuru Ph 1") -> 0 | R13: =SUMIFS(Ledger!$C$5:$C$109,Ledger!$F$5:$F$109,$A13,Ledger!$B$5:$B$109,"NIC Otjomuise Ext 10 (Erf 5221)") -> 0 | S13: =SUMIFS(Ledger!$C$5:$C$109,Ledger!$F$5:$F$109,$A13,Ledger!$B$5:$B$109,"Heavens Ark — Otjomuise") -> 0
A14: 43435 | B14: =SUMIFS(Ledger!$D$5:$D$109,Ledger!$F$5:$F$109,$A14) -> 0 | C14: =SUMIFS(Ledger!$E$5:$E$109,Ledger!$F$5:$F$109,$A14) -> 10443745 | D14: =B14+C14 -> 10443745 | E14: =D14 -> 10443745 | F14: =SUMIFS(Ledger!$C$5:$C$109,Ledger!$F$5:$F$109,$A14,Ledger!$B$5:$B$109,"Erf 1470 Khomasdal") -> 0 | G14: =SUMIFS(Ledger!$C$5:$C$109,Ledger!$F$5:$F$109,$A14,Ledger!$B$5:$B$109,"Dunescape Villas (Erf 5159)") -> 0 | H14: =SUMIFS(Ledger!$C$5:$C$109,Ledger!$F$5:$F$109,$A14,Ledger!$B$5:$B$109,"PAM Tree (Erf 5758)") -> 0 | I14: =SUMIFS(Ledger!$C$5:$C$109,Ledger!$F$5:$F$109,$A14,Ledger!$B$5:$B$109,"Turnstone Villas (Erf 8939)") -> 0 | J14: =SUMIFS(Ledger!$C$5:$C$109,Ledger!$F$5:$F$109,$A14,Ledger!$B$5:$B$109,"Lithon Nkurenkuru Ext 2") -> 0 | K14: =SUMIFS(Ledger!$C$5:$C$109,Ledger!$F$5:$F$109,$A14,Ledger!$B$5:$B$109,"Mondesa Palms") -> 0 | L14: =SUMIFS(Ledger!$C$5:$C$109,Ledger!$F$5:$F$109,$A14,Ledger!$B$5:$B$109,"The Ridge — Rocky Crest Ext 4") -> 0 | M14: =SUMIFS(Ledger!$C$5:$C$109,Ledger!$F$5:$F$109,$A14,Ledger!$B$5:$B$109,"Mango Cove (Otjomuise Ext 10)") -> 0 | N14: =SUMIFS(Ledger!$C$5:$C$109,Ledger!$F$5:$F$109,$A14,Ledger!$B$5:$B$109,"C-Breeze Heights") -> 0 | O14: =SUMIFS(Ledger!$C$5:$C$109,Ledger!$F$5:$F$109,$A14,Ledger!$B$5:$B$109,"Tama Estates") -> 0 | P14: =SUMIFS(Ledger!$C$5:$C$109,Ledger!$F$5:$F$109,$A14,Ledger!$B$5:$B$109,"Duma Tau — Kronlein") -> 10443745 | Q14: =SUMIFS(Ledger!$C$5:$C$109,Ledger!$F$5:$F$109,$A14,Ledger!$B$5:$B$109,"LIH Nkurenkuru Ph 1") -> 0 | R14: =SUMIFS(Ledger!$C$5:$C$109,Ledger!$F$5:$F$109,$A14,Ledger!$B$5:$B$109,"NIC Otjomuise Ext 10 (Erf 5221)") -> 0 | S14: =SUMIFS(Ledger!$C$5:$C$109,Ledger!$F$5:$F$109,$A14,Ledger!$B$5:$B$109,"Heavens Ark — Otjomuise") -> 0
A15: 43466 | B15: =SUMIFS(Ledger!$D$5:$D$109,Ledger!$F$5:$F$109,$A15) -> -12450000 | C15: =SUMIFS(Ledger!$E$5:$E$109,Ledger!$F$5:$F$109,$A15) -> 4425225 | D15: =B15+C15 -> -8024775 | E15: =D15 -> -8024775 | F15: =SUMIFS(Ledger!$C$5:$C$109,Ledger!$F$5:$F$109,$A15,Ledger!$B$5:$B$109,"Erf 1470 Khomasdal") -> 0 | G15: =SUMIFS(Ledger!$C$5:$C$109,Ledger!$F$5:$F$109,$A15,Ledger!$B$5:$B$109,"Dunescape Villas (Erf 5159)") -> 0 | H15: =SUMIFS(Ledger!$C$5:$C$109,Ledger!$F$5:$F$109,$A15,Ledger!$B$5:$B$109,"PAM Tree (Erf 5758)") -> 0 | I15: =SUMIFS(Ledger!$C$5:$C$109,Ledger!$F$5:$F$109,$A15,Ledger!$B$5:$B$109,"Turnstone Villas (Erf 8939)") -> 0 | J15: =SUMIFS(Ledger!$C$5:$C$109,Ledger!$F$5:$F$109,$A15,Ledger!$B$5:$B$109,"Lithon Nkurenkuru Ext 2") -> 0 | K15: =SUMIFS(Ledger!$C$5:$C$109,Ledger!$F$5:$F$109,$A15,Ledger!$B$5:$B$109,"Mondesa Palms") -> 0 | L15: =SUMIFS(Ledger!$C$5:$C$109,Ledger!$F$5:$F$109,$A15,Ledger!$B$5:$B$109,"The Ridge — Rocky Crest Ext 4") -> 0 | M15: =SUMIFS(Ledger!$C$5:$C$109,Ledger!$F$5:$F$109,$A15,Ledger!$B$5:$B$109,"Mango Cove (Otjomuise Ext 10)") -> 0 | N15: =SUMIFS(Ledger!$C$5:$C$109,Ledger!$F$5:$F$109,$A15,Ledger!$B$5:$B$109,"C-Breeze Heights") -> 0 | O15: =SUMIFS(Ledger!$C$5:$C$109,Ledger!$F$5:$F$109,$A15,Ledger!$B$5:$B$109,"Tama Estates") -> 0 | P15: =SUMIFS(Ledger!$C$5:$C$109,Ledger!$F$5:$F$109,$A15,Ledger!$B$5:$B$109,"Duma Tau — Kronlein") -> 4425225 | Q15: =SUMIFS(Ledger!$C$5:$C$109,Ledger!$F$5:$F$109,$A15,Ledger!$B$5:$B$109,"LIH Nkurenkuru Ph 1") -> 0 | R15: =SUMIFS(Ledger!$C$5:$C$109,Ledger!$F$5:$F$109,$A15,Ledger!$B$5:$B$109,"NIC Otjomuise Ext 10 (Erf 5221)") -> 0 | S15: =SUMIFS(Ledger!$C$5:$C$109,Ledger!$F$5:$F$109,$A15,Ledger!$B$5:$B$109,"Heavens Ark — Otjomuise") -> 0
A16: 43497 | B16: =SUMIFS(Ledger!$D$5:$D$109,Ledger!$F$5:$F$109,$A16) -> -10400000 | C16: =SUMIFS(Ledger!$E$5:$E$109,Ledger!$F$5:$F$109,$A16) -> 3242310 | D16: =B16+C16 -> -7157690 | E16: =D16 -> -7157690 | F16: =SUMIFS(Ledger!$C$5:$C$109,Ledger!$F$5:$F$109,$A16,Ledger!$B$5:$B$109,"Erf 1470 Khomasdal") -> 0 | G16: =SUMIFS(Ledger!$C$5:$C$109,Ledger!$F$5:$F$109,$A16,Ledger!$B$5:$B$109,"Dunescape Villas (Erf 5159)") -> 0 | H16: =SUMIFS(Ledger!$C$5:$C$109,Ledger!$F$5:$F$109,$A16,Ledger!$B$5:$B$109,"PAM Tree (Erf 5758)") -> 0 | I16: =SUMIFS(Ledger!$C$5:$C$109,Ledger!$F$5:$F$109,$A16,Ledger!$B$5:$B$109,"Turnstone Villas (Erf 8939)") -> 0 | J16: =SUMIFS(Ledger!$C$5:$C$109,Ledger!$F$5:$F$109,$A16,Ledger!$B$5:$B$109,"Lithon Nkurenkuru Ext 2") -> 0 | K16: =SUMIFS(Ledger!$C$5:$C$109,Ledger!$F$5:$F$109,$A16,Ledger!$B$5:$B$109,"Mondesa Palms") -> 0 | L16: =SUMIFS(Ledger!$C$5:$C$109,Ledger!$F$5:$F$109,$A16,Ledger!$B$5:$B$109,"The Ridge — Rocky Crest Ext 4") -> 0 | M16: =SUMIFS(Ledger!$C$5:$C$109,Ledger!$F$5:$F$109,$A16,Ledger!$B$5:$B$109,"Mango Cove (Otjomuise Ext 10)") -> 0 | N16: =SUMIFS(Ledger!$C$5:$C$109,Ledger!$F$5:$F$109,$A16,Ledger!$B$5:$B$109,"C-Breeze Heights") -> 0 | O16: =SUMIFS(Ledger!$C$5:$C$109,Ledger!$F$5:$F$109,$A16,Ledger!$B$5:$B$109,"Tama Estates") -> 0 | P16: =SUMIFS(Ledger!$C$5:$C$109,Ledger!$F$5:$F$109,$A16,Ledger!$B$5:$B$109,"Duma Tau — Kronlein") -> 3242310 | Q16: =SUMIFS(Ledger!$C$5:$C$109,Ledger!$F$5:$F$109,$A16,Ledger!$B$5:$B$109,"LIH Nkurenkuru Ph 1") -> 0 | R16: =SUMIFS(Ledger!$C$5:$C$109,Ledger!$F$5:$F$109,$A16,Ledger!$B$5:$B$109,"NIC Otjomuise Ext 10 (Erf 5221)") -> 0 | S16: =SUMIFS(Ledger!$C$5:$C$109,Ledger!$F$5:$F$109,$A16,Ledger!$B$5:$B$109,"Heavens Ark — Otjomuise") -> 0
... A34: 44531 | B34: =SUMIFS(Ledger!$D$5:$D$109,Ledger!$F$5:$F$109,$A34) -> 0 | C34: =SUMIFS(Ledger!$E$5:$E$109,Ledger!$F$5:$F$109,$A34) -> 4575267.8 | D34: =B34+C34 -> 4575267.8 | E34: =D34 -> 4575267.8 | F34: =SUMIFS(Ledger!$C$5:$C$109,Ledger!$F$5:$F$109,$A34,Ledger!$B$5:$B$109,"Erf 1470 Khomasdal") -> 0 | G34: =SUMIFS(Ledger!$C$5:$C$109,Ledger!$F$5:$F$109,$A34,Ledger!$B$5:$B$109,"Dunescape Villas (Erf 5159)") -> 0 | H34: =SUMIFS(Ledger!$C$5:$C$109,Ledger!$F$5:$F$109,$A34,Ledger!$B$5:$B$109,"PAM Tree (Erf 5758)") -> 0 | I34: =SUMIFS(Ledger!$C$5:$C$109,Ledger!$F$5:$F$109,$A34,Ledger!$B$5:$B$109,"Turnstone Villas (Erf 8939)") -> 0 | J34: =SUMIFS(Ledger!$C$5:$C$109,Ledger!$F$5:$F$109,$A34,Ledger!$B$5:$B$109,"Lithon Nkurenkuru Ext 2") -> 0 | K34: =SUMIFS(Ledger!$C$5:$C$109,Ledger!$F$5:$F$109,$A34,Ledger!$B$5:$B$109,"Mondesa Palms") -> 0 | L34: =SUMIFS(Ledger!$C$5:$C$109,Ledger!$F$5:$F$109,$A34,Ledger!$B$5:$B$109,"The Ridge — Rocky Crest Ext 4") -> 0 | M34: =SUMIFS(Ledger!$C$5:$C$109,Ledger!$F$5:$F$109,$A34,Ledger!$B$5:$B$109,"Mango Cove (Otjomuise Ext 10)") -> 0 | N34: =SUMIFS(Ledger!$C$5:$C$109,Ledger!$F$5:$F$109,$A34,Ledger!$B$5:$B$109,"C-Breeze Heights") -> 0 | O34: =SUMIFS(Ledger!$C$5:$C$109,Ledger!$F$5:$F$109,$A34,Ledger!$B$5:$B$109,"Tama Estates") -> 0 | P34: =SUMIFS(Ledger!$C$5:$C$109,Ledger!$F$5:$F$109,$A34,Ledger!$B$5:$B$109,"Duma Tau — Kronlein") -> 3481490.1 | Q34: =SUMIFS(Ledger!$C$5:$C$109,Ledger!$F$5:$F$109,$A34,Ledger!$B$5:$B$109,"LIH Nkurenkuru Ph 1") -> 0 | R34: =SUMIFS(Ledger!$C$5:$C$109,Ledger!$F$5:$F$109,$A34,Ledger!$B$5:$B$109,"NIC Otjomuise Ext 10 (Erf 5221)") -> 0 | S34: =SUMIFS(Ledger!$C$5:$C$109,Ledger!$F$5:$F$109,$A34,Ledger!$B$5:$B$109,"Heavens Ark — Otjomuise") -> 0
A35: 44682 | B35: =SUMIFS(Ledger!$D$5:$D$109,Ledger!$F$5:$F$109,$A35) -> -5500000 | C35: =SUMIFS(Ledger!$E$5:$E$109,Ledger!$F$5:$F$109,$A35) -> 0 | D35: =B35+C35 -> -5500000 | E35: =E34+D35 -> -924732.24 | F35: =SUMIFS(Ledger!$C$5:$C$109,Ledger!$F$5:$F$109,$A35,Ledger!$B$5:$B$109,"Erf 1470 Khomasdal") -> 0 | G35: =SUMIFS(Ledger!$C$5:$C$109,Ledger!$F$5:$F$109,$A35,Ledger!$B$5:$B$109,"Dunescape Villas (Erf 5159)") -> 0 | H35: =SUMIFS(Ledger!$C$5:$C$109,Ledger!$F$5:$F$109,$A35,Ledger!$B$5:$B$109,"PAM Tree (Erf 5758)") -> 0 | I35: =SUMIFS(Ledger!$C$5:$C$109,Ledger!$F$5:$F$109,$A35,Ledger!$B$5:$B$109,"Turnstone Villas (Erf 8939)") -> 0 | J35: =SUMIFS(Ledger!$C$5:$C$109,Ledger!$F$5:$F$109,$A35,Ledger!$B$5:$B$109,"Lithon Nkurenkuru Ext 2") -> 0 | K35: =SUMIFS(Ledger!$C$5:$C$109,Ledger!$F$5:$F$109,$A35,Ledger!$B$5:$B$109,"Mondesa Palms") -> 0 | L35: =SUMIFS(Ledger!$C$5:$C$109,Ledger!$F$5:$F$109,$A35,Ledger!$B$5:$B$109,"The Ridge — Rocky Crest Ext 4") -> 0 | M35: =SUMIFS(Ledger!$C$5:$C$109,Ledger!$F$5:$F$109,$A35,Ledger!$B$5:$B$109,"Mango Cove (Otjomuise Ext 10)") -> 0 | N35: =SUMIFS(Ledger!$C$5:$C$109,Ledger!$F$5:$F$109,$A35,Ledger!$B$5:$B$109,"C-Breeze Heights") -> 0 | O35: =SUMIFS(Ledger!$C$5:$C$109,Ledger!$F$5:$F$109,$A35,Ledger!$B$5:$B$109,"Tama Estates") -> 0 | P35: =SUMIFS(Ledger!$C$5:$C$109,Ledger!$F$5:$F$109,$A35,Ledger!$B$5:$B$109,"Duma Tau — Kronlein") -> 0 | Q35: =SUMIFS(Ledger!$C$5:$C$109,Ledger!$F$5:$F$109,$A35,Ledger!$B$5:$B$109,"LIH Nkurenkuru Ph 1") -> 0 | R35: =SUMIFS(Ledger!$C$5:$C$109,Ledger!$F$5:$F$109,$A35,Ledger!$B$5:$B$109,"NIC Otjomuise Ext 10 (Erf 5221)") -> 0 | S35: =SUMIFS(Ledger!$C$5:$C$109,Ledger!$F$5:$F$109,$A35,Ledger!$B$5:$B$109,"Heavens Ark — Otjomuise") -> 0
A36: 44774 | B36: =SUMIFS(Ledger!$D$5:$D$109,Ledger!$F$5:$F$109,$A36) -> -7000000 | C36: =SUMIFS(Ledger!$E$5:$E$109,Ledger!$F$5:$F$109,$A36) -> 0 | D36: =B36+C36 -> -7000000 | E36: =D36 -> -7000000 | F36: =SUMIFS(Ledger!$C$5:$C$109,Ledger!$F$5:$F$109,$A36,Ledger!$B$5:$B$109,"Erf 1470 Khomasdal") -> 0 | G36: =SUMIFS(Ledger!$C$5:$C$109,Ledger!$F$5:$F$109,$A36,Ledger!$B$5:$B$109,"Dunescape Villas (Erf 5159)") -> 0 | H36: =SUMIFS(Ledger!$C$5:$C$109,Ledger!$F$5:$F$109,$A36,Ledger!$B$5:$B$109,"PAM Tree (Erf 5758)") -> 0 | I36: =SUMIFS(Ledger!$C$5:$C$109,Ledger!$F$5:$F$109,$A36,Ledger!$B$5:$B$109,"Turnstone Villas (Erf 8939)") -> 0 | J36: =SUMIFS(Ledger!$C$5:$C$109,Ledger!$F$5:$F$109,$A36,Ledger!$B$5:$B$109,"Lithon Nkurenkuru Ext 2") -> 0 | K36: =SUMIFS(Ledger!$C$5:$C$109,Ledger!$F$5:$F$109,$A36,Ledger!$B$5:$B$109,"Mondesa Palms") -> 0 | L36: =SUMIFS(Ledger!$C$5:$C$109,Ledger!$F$5:$F$109,$A36,Ledger!$B$5:$B$109,"The Ridge — Rocky Crest Ext 4") -> 0 | M36: =SUMIFS(Ledger!$C$5:$C$109,Ledger!$F$5:$F$109,$A36,Ledger!$B$5:$B$109,"Mango Cove (Otjomuise Ext 10)") -> 0 | N36: =SUMIFS(Ledger!$C$5:$C$109,Ledger!$F$5:$F$109,$A36,Ledger!$B$5:$B$109,"C-Breeze Heights") -> 0 | O36: =SUMIFS(Ledger!$C$5:$C$109,Ledger!$F$5:$F$109,$A36,Ledger!$B$5:$B$109,"Tama Estates") -> 0 | P36: =SUMIFS(Ledger!$C$5:$C$109,Ledger!$F$5:$F$109,$A36,Ledger!$B$5:$B$109,"Duma Tau — Kronlein") -> 0 | Q36: =SUMIFS(Ledger!$C$5:$C$109,Ledger!$F$5:$F$109,$A36,Ledger!$B$5:$B$109,"LIH Nkurenkuru Ph 1") -> 0 | R36: =SUMIFS(Ledger!$C$5:$C$109,Ledger!$F$5:$F$109,$A36,Ledger!$B$5:$B$109,"NIC Otjomuise Ext 10 (Erf 5221)") -> 0 | S36: =SUMIFS(Ledger!$C$5:$C$109,Ledger!$F$5:$F$109,$A36,Ledger!$B$5:$B$109,"Heavens Ark — Otjomuise") -> 0
A37: 44866 | B37: =SUMIFS(Ledger!$D$5:$D$109,Ledger!$F$5:$F$109,$A37) -> 0 | C37: =SUMIFS(Ledger!$E$5:$E$109,Ledger!$F$5:$F$109,$A37) -> 0 | D37: =B37+C37 -> 0 | E37: =D37 -> 0 | F37: =SUMIFS(Ledger!$C$5:$C$109,Ledger!$F$5:$F$109,$A37,Ledger!$B$5:$B$109,"Erf 1470 Khomasdal") -> 0 | G37: =SUMIFS(Ledger!$C$5:$C$109,Ledger!$F$5:$F$109,$A37,Ledger!$B$5:$B$109,"Dunescape Villas (Erf 5159)") -> 0 | H37: =SUMIFS(Ledger!$C$5:$C$109,Ledger!$F$5:$F$109,$A37,Ledger!$B$5:$B$109,"PAM Tree (Erf 5758)") -> 0 | I37: =SUMIFS(Ledger!$C$5:$C$109,Ledger!$F$5:$F$109,$A37,Ledger!$B$5:$B$109,"Turnstone Villas (Erf 8939)") -> 0 | J37: =SUMIFS(Ledger!$C$5:$C$109,Ledger!$F$5:$F$109,$A37,Ledger!$B$5:$B$109,"Lithon Nkurenkuru Ext 2") -> 0 | K37: =SUMIFS(Ledger!$C$5:$C$109,Ledger!$F$5:$F$109,$A37,Ledger!$B$5:$B$109,"Mondesa Palms") -> 0 | L37: =SUMIFS(Ledger!$C$5:$C$109,Ledger!$F$5:$F$109,$A37,Ledger!$B$5:$B$109,"The Ridge — Rocky Crest Ext 4") -> 0 | M37: =SUMIFS(Ledger!$C$5:$C$109,Ledger!$F$5:$F$109,$A37,Ledger!$B$5:$B$109,"Mango Cove (Otjomuise Ext 10)") -> 0 | N37: =SUMIFS(Ledger!$C$5:$C$109,Ledger!$F$5:$F$109,$A37,Ledger!$B$5:$B$109,"C-Breeze Heights") -> 0 | O37: =SUMIFS(Ledger!$C$5:$C$109,Ledger!$F$5:$F$109,$A37,Ledger!$B$5:$B$109,"Tama Estates") -> 0 | P37: =SUMIFS(Ledger!$C$5:$C$109,Ledger!$F$5:$F$109,$A37,Ledger!$B$5:$B$109,"Duma Tau — Kronlein") -> 0 | Q37: =SUMIFS(Ledger!$C$5:$C$109,Ledger!$F$5:$F$109,$A37,Ledger!$B$5:$B$109,"LIH Nkurenkuru Ph 1") -> 0 | R37: =SUMIFS(Ledger!$C$5:$C$109,Ledger!$F$5:$F$109,$A37,Ledger!$B$5:$B$109,"NIC Otjomuise Ext 10 (Erf 5221)") -> 0 | S37: =SUMIFS(Ledger!$C$5:$C$109,Ledger!$F$5:$F$109,$A37,Ledger!$B$5:$B$109,"Heavens Ark — Otjomuise") -> 0
A38: 44896 | B38: =SUMIFS(Ledger!$D$5:$D$109,Ledger!$F$5:$F$109,$A38) -> 0 | C38: =SUMIFS(Ledger!$E$5:$E$109,Ledger!$F$5:$F$109,$A38) -> 0 | D38: =B38+C38 -> 0 | E38: =D38 -> 0 | F38: =SUMIFS(Ledger!$C$5:$C$109,Ledger!$F$5:$F$109,$A38,Ledger!$B$5:$B$109,"Erf 1470 Khomasdal") -> 0 | G38: =SUMIFS(Ledger!$C$5:$C$109,Ledger!$F$5:$F$109,$A38,Ledger!$B$5:$B$109,"Dunescape Villas (Erf 5159)") -> 0 | H38: =SUMIFS(Ledger!$C$5:$C$109,Ledger!$F$5:$F$109,$A38,Ledger!$B$5:$B$109,"PAM Tree (Erf 5758)") -> 0 | I38: =SUMIFS(Ledger!$C$5:$C$109,Ledger!$F$5:$F$109,$A38,Ledger!$B$5:$B$109,"Turnstone Villas (Erf 8939)") -> 0 | J38: =SUMIFS(Ledger!$C$5:$C$109,Ledger!$F$5:$F$109,$A38,Ledger!$B$5:$B$109,"Lithon Nkurenkuru Ext 2") -> 0 | K38: =SUMIFS(Ledger!$C$5:$C$109,Ledger!$F$5:$F$109,$A38,Ledger!$B$5:$B$109,"Mondesa Palms") -> 0 | L38: =SUMIFS(Ledger!$C$5:$C$109,Ledger!$F$5:$F$109,$A38,Ledger!$B$5:$B$109,"The Ridge — Rocky Crest Ext 4") -> 0 | M38: =SUMIFS(Ledger!$C$5:$C$109,Ledger!$F$5:$F$109,$A38,Ledger!$B$5:$B$109,"Mango Cove (Otjomuise Ext 10)") -> 0 | N38: =SUMIFS(Ledger!$C$5:$C$109,Ledger!$F$5:$F$109,$A38,Ledger!$B$5:$B$109,"C-Breeze Heights") -> 0 | O38: =SUMIFS(Ledger!$C$5:$C$109,Ledger!$F$5:$F$109,$A38,Ledger!$B$5:$B$109,"Tama Estates") -> 0 | P38: =SUMIFS(Ledger!$C$5:$C$109,Ledger!$F$5:$F$109,$A38,Ledger!$B$5:$B$109,"Duma Tau — Kronlein") -> 0 | Q38: =SUMIFS(Ledger!$C$5:$C$109,Ledger!$F$5:$F$109,$A38,Ledger!$B$5:$B$109,"LIH Nkurenkuru Ph 1") -> 0 | R38: =SUMIFS(Ledger!$C$5:$C$109,Ledger!$F$5:$F$109,$A38,Ledger!$B$5:$B$109,"NIC Otjomuise Ext 10 (Erf 5221)") -> 0 | S38: =SUMIFS(Ledger!$C$5:$C$109,Ledger!$F$5:$F$109,$A38,Ledger!$B$5:$B$109,"Heavens Ark — Otjomuise") -> 0
A39: 44927 | B39: =SUMIFS(Ledger!$D$5:$D$109,Ledger!$F$5:$F$109,$A39) -> 0 | C39: =SUMIFS(Ledger!$E$5:$E$109,Ledger!$F$5:$F$109,$A39) -> 0 | D39: =B39+C39 -> 0 | E39: =D39 -> 0 | F39: =SUMIFS(Ledger!$C$5:$C$109,Ledger!$F$5:$F$109,$A39,Ledger!$B$5:$B$109,"Erf 1470 Khomasdal") -> 0 | G39: =SUMIFS(Ledger!$C$5:$C$109,Ledger!$F$5:$F$109,$A39,Ledger!$B$5:$B$109,"Dunescape Villas (Erf 5159)") -> 0 | H39: =SUMIFS(Ledger!$C$5:$C$109,Ledger!$F$5:$F$109,$A39,Ledger!$B$5:$B$109,"PAM Tree (Erf 5758)") -> 0 | I39: =SUMIFS(Ledger!$C$5:$C$109,Ledger!$F$5:$F$109,$A39,Ledger!$B$5:$B$109,"Turnstone Villas (Erf 8939)") -> 0 | J39: =SUMIFS(Ledger!$C$5:$C$109,Ledger!$F$5:$F$109,$A39,Ledger!$B$5:$B$109,"Lithon Nkurenkuru Ext 2") -> 0 | K39: =SUMIFS(Ledger!$C$5:$C$109,Ledger!$F$5:$F$109,$A39,Ledger!$B$5:$B$109,"Mondesa Palms") -> 0 | L39: =SUMIFS(Ledger!$C$5:$C$109,Ledger!$F$5:$F$109,$A39,Ledger!$B$5:$B$109,"The Ridge — Rocky Crest Ext 4") -> 0 | M39: =SUMIFS(Ledger!$C$5:$C$109,Ledger!$F$5:$F$109,$A39,Ledger!$B$5:$B$109,"Mango Cove (Otjomuise Ext 10)") -> 0 | N39: =SUMIFS(Ledger!$C$5:$C$109,Ledger!$F$5:$F$109,$A39,Ledger!$B$5:$B$109,"C-Breeze Heights") -> 0 | O39: =SUMIFS(Ledger!$C$5:$C$109,Ledger!$F$5:$F$109,$A39,Ledger!$B$5:$B$109,"Tama Estates") -> 0 | P39: =SUMIFS(Ledger!$C$5:$C$109,Ledger!$F$5:$F$109,$A39,Ledger!$B$5:$B$109,"Duma Tau — Kronlein") -> 0 | Q39: =SUMIFS(Ledger!$C$5:$C$109,Ledger!$F$5:$F$109,$A39,Ledger!$B$5:$B$109,"LIH Nkurenkuru Ph 1") -> 0 | R39: =SUMIFS(Ledger!$C$5:$C$109,Ledger!$F$5:$F$109,$A39,Ledger!$B$5:$B$109,"NIC Otjomuise Ext 10 (Erf 5221)") -> 0 | S39: =SUMIFS(Ledger!$C$5:$C$109,Ledger!$F$5:$F$109,$A39,Ledger!$B$5:$B$109,"Heavens Ark — Otjomuise") -> 0
A40: 44986 | B40: =SUMIFS(Ledger!$D$5:$D$109,Ledger!$F$5:$F$109,$A40) -> 0 | C40: =SUMIFS(Ledger!$E$5:$E$109,Ledger!$F$5:$F$109,$A40) -> 0 | D40: =B40+C40 -> 0 | E40: =D40 -> 0 | F40: =SUMIFS(Ledger!$C$5:$C$109,Ledger!$F$5:$F$109,$A40,Ledger!$B$5:$B$109,"Erf 1470 Khomasdal") -> 0 | G40: =SUMIFS(Ledger!$C$5:$C$109,Ledger!$F$5:$F$109,$A40,Ledger!$B$5:$B$109,"Dunescape Villas (Erf 5159)") -> 0 | H40: =SUMIFS(Ledger!$C$5:$C$109,Ledger!$F$5:$F$109,$A40,Ledger!$B$5:$B$109,"PAM Tree (Erf 5758)") -> 0 | I40: =SUMIFS(Ledger!$C$5:$C$109,Ledger!$F$5:$F$109,$A40,Ledger!$B$5:$B$109,"Turnstone Villas (Erf 8939)") -> 0 | J40: =SUMIFS(Ledger!$C$5:$C$109,Ledger!$F$5:$F$109,$A40,Ledger!$B$5:$B$109,"Lithon Nkurenkuru Ext 2") -> 0 | K40: =SUMIFS(Ledger!$C$5:$C$109,Ledger!$F$5:$F$109,$A40,Ledger!$B$5:$B$109,"Mondesa Palms") -> 0 | L40: =SUMIFS(Ledger!$C$5:$C$109,Ledger!$F$5:$F$109,$A40,Ledger!$B$5:$B$109,"The Ridge — Rocky Crest Ext 4") -> 0 | M40: =SUMIFS(Ledger!$C$5:$C$109,Ledger!$F$5:$F$109,$A40,Ledger!$B$5:$B$109,"Mango Cove (Otjomuise Ext 10)") -> 0 | N40: =SUMIFS(Ledger!$C$5:$C$109,Ledger!$F$5:$F$109,$A40,Ledger!$B$5:$B$109,"C-Breeze Heights") -> 0 | O40: =SUMIFS(Ledger!$C$5:$C$109,Ledger!$F$5:$F$109,$A40,Ledger!$B$5:$B$109,"Tama Estates") -> 0 | P40: =SUMIFS(Ledger!$C$5:$C$109,Ledger!$F$5:$F$109,$A40,Ledger!$B$5:$B$109,"Duma Tau — Kronlein") -> 0 | Q40: =SUMIFS(Ledger!$C$5:$C$109,Ledger!$F$5:$F$109,$A40,Ledger!$B$5:$B$109,"LIH Nkurenkuru Ph 1") -> 0 | R40: =SUMIFS(Ledger!$C$5:$C$109,Ledger!$F$5:$F$109,$A40,Ledger!$B$5:$B$109,"NIC Otjomuise Ext 10 (Erf 5221)") -> 0 | S40: =SUMIFS(Ledger!$C$5:$C$109,Ledger!$F$5:$F$109,$A40,Ledger!$B$5:$B$109,"Heavens Ark — Otjomuise") -> 0
A41: 45017 | B41: =SUMIFS(Ledger!$D$5:$D$109,Ledger!$F$5:$F$109,$A41) -> 0 | C41: =SUMIFS(Ledger!$E$5:$E$109,Ledger!$F$5:$F$109,$A41) -> 6983276.3 | D41: =B41+C41 -> 6983276.3 | E41: =D41 -> 6983276.3 | F41: =SUMIFS(Ledger!$C$5:$C$109,Ledger!$F$5:$F$109,$A41,Ledger!$B$5:$B$109,"Erf 1470 Khomasdal") -> 0 | G41: =SUMIFS(Ledger!$C$5:$C$109,Ledger!$F$5:$F$109,$A41,Ledger!$B$5:$B$109,"Dunescape Villas (Erf 5159)") -> 0 | H41: =SUMIFS(Ledger!$C$5:$C$109,Ledger!$F$5:$F$109,$A41,Ledger!$B$5:$B$109,"PAM Tree (Erf 5758)") -> 0 | I41: =SUMIFS(Ledger!$C$5:$C$109,Ledger!$F$5:$F$109,$A41,Ledger!$B$5:$B$109,"Turnstone Villas (Erf 8939)") -> 0 | J41: =SUMIFS(Ledger!$C$5:$C$109,Ledger!$F$5:$F$109,$A41,Ledger!$B$5:$B$109,"Lithon Nkurenkuru Ext 2") -> 0 | K41: =SUMIFS(Ledger!$C$5:$C$109,Ledger!$F$5:$F$109,$A41,Ledger!$B$5:$B$109,"Mondesa Palms") -> 0 | L41: =SUMIFS(Ledger!$C$5:$C$109,Ledger!$F$5:$F$109,$A41,Ledger!$B$5:$B$109,"The Ridge — Rocky Crest Ext 4") -> 0 | M41: =SUMIFS(Ledger!$C$5:$C$109,Ledger!$F$5:$F$109,$A41,Ledger!$B$5:$B$109,"Mango Cove (Otjomuise Ext 10)") -> 0 | N41: =SUMIFS(Ledger!$C$5:$C$109,Ledger!$F$5:$F$109,$A41,Ledger!$B$5:$B$109,"C-Breeze Heights") -> 0 | O41: =SUMIFS(Ledger!$C$5:$C$109,Ledger!$F$5:$F$109,$A41,Ledger!$B$5:$B$109,"Tama Estates") -> 0 | P41: =SUMIFS(Ledger!$C$5:$C$109,Ledger!$F$5:$F$109,$A41,Ledger!$B$5:$B$109,"Duma Tau — Kronlein") -> 694476.87 | Q41: =SUMIFS(Ledger!$C$5:$C$109,Ledger!$F$5:$F$109,$A41,Ledger!$B$5:$B$109,"LIH Nkurenkuru Ph 1") -> 0 | R41: =SUMIFS(Ledger!$C$5:$C$109,Ledger!$F$5:$F$109,$A41,Ledger!$B$5:$B$109,"NIC Otjomuise Ext 10 (Erf 5221)") -> 0 | S41: =SUMIFS(Ledger!$C$5:$C$109,Ledger!$F$5:$F$109,$A41,Ledger!$B$5:$B$109,"Heavens Ark — Otjomuise") -> 0
A42: 45047 | B42: =SUMIFS(Ledger!$D$5:$D$109,Ledger!$F$5:$F$109,$A42) -> 0 | C42: =SUMIFS(Ledger!$E$5:$E$109,Ledger!$F$5:$F$109,$A42) -> 0 | D42: =B42+C42 -> 0 | E42: =D42 -> 0 | F42: =SUMIFS(Ledger!$C$5:$C$109,Ledger!$F$5:$F$109,$A42,Ledger!$B$5:$B$109,"Erf 1470 Khomasdal") -> 0 | G42: =SUMIFS(Ledger!$C$5:$C$109,Ledger!$F$5:$F$109,$A42,Ledger!$B$5:$B$109,"Dunescape Villas (Erf 5159)") -> 0 | H42: =SUMIFS(Ledger!$C$5:$C$109,Ledger!$F$5:$F$109,$A42,Ledger!$B$5:$B$109,"PAM Tree (Erf 5758)") -> 0 | I42: =SUMIFS(Ledger!$C$5:$C$109,Ledger!$F$5:$F$109,$A42,Ledger!$B$5:$B$109,"Turnstone Villas (Erf 8939)") -> 0 | J42: =SUMIFS(Ledger!$C$5:$C$109,Ledger!$F$5:$F$109,$A42,Ledger!$B$5:$B$109,"Lithon Nkurenkuru Ext 2") -> 0 | K42: =SUMIFS(Ledger!$C$5:$C$109,Ledger!$F$5:$F$109,$A42,Ledger!$B$5:$B$109,"Mondesa Palms") -> 0 | L42: =SUMIFS(Ledger!$C$5:$C$109,Ledger!$F$5:$F$109,$A42,Ledger!$B$5:$B$109,"The Ridge — Rocky Crest Ext 4") -> 0 | M42: =SUMIFS(Ledger!$C$5:$C$109,Ledger!$F$5:$F$109,$A42,Ledger!$B$5:$B$109,"Mango Cove (Otjomuise Ext 10)") -> 0 | N42: =SUMIFS(Ledger!$C$5:$C$109,Ledger!$F$5:$F$109,$A42,Ledger!$B$5:$B$109,"C-Breeze Heights") -> 0 | O42: =SUMIFS(Ledger!$C$5:$C$109,Ledger!$F$5:$F$109,$A42,Ledger!$B$5:$B$109,"Tama Estates") -> 0 | P42: =SUMIFS(Ledger!$C$5:$C$109,Ledger!$F$5:$F$109,$A42,Ledger!$B$5:$B$109,"Duma Tau — Kronlein") -> 0 | Q42: =SUMIFS(Ledger!$C$5:$C$109,Ledger!$F$5:$F$109,$A42,Ledger!$B$5:$B$109,"LIH Nkurenkuru Ph 1") -> 0 | R42: =SUMIFS(Ledger!$C$5:$C$109,Ledger!$F$5:$F$109,$A42,Ledger!$B$5:$B$109,"NIC Otjomuise Ext 10 (Erf 5221)") -> 0 | S42: =SUMIFS(Ledger!$C$5:$C$109,Ledger!$F$5:$F$109,$A42,Ledger!$B$5:$B$109,"Heavens Ark — Otjomuise") -> 0
A43: 45078 | B43: =SUMIFS(Ledger!$D$5:$D$109,Ledger!$F$5:$F$109,$A43) -> 0 | C43: =SUMIFS(Ledger!$E$5:$E$109,Ledger!$F$5:$F$109,$A43) -> 1515807.3 | D43: =B43+C43 -> 1515807.3 | E43: =D43 -> 1515807.3 | F43: =SUMIFS(Ledger!$C$5:$C$109,Ledger!$F$5:$F$109,$A43,Ledger!$B$5:$B$109,"Erf 1470 Khomasdal") -> 0 | G43: =SUMIFS(Ledger!$C$5:$C$109,Ledger!$F$5:$F$109,$A43,Ledger!$B$5:$B$109,"Dunescape Villas (Erf 5159)") -> 0 | H43: =SUMIFS(Ledger!$C$5:$C$109,Ledger!$F$5:$F$109,$A43,Ledger!$B$5:$B$109,"PAM Tree (Erf 5758)") -> 0 | I43: =SUMIFS(Ledger!$C$5:$C$109,Ledger!$F$5:$F$109,$A43,Ledger!$B$5:$B$109,"Turnstone Villas (Erf 8939)") -> 0 | J43: =SUMIFS(Ledger!$C$5:$C$109,Ledger!$F$5:$F$109,$A43,Ledger!$B$5:$B$109,"Lithon Nkurenkuru Ext 2") -> 0 | K43: =SUMIFS(Ledger!$C$5:$C$109,Ledger!$F$5:$F$109,$A43,Ledger!$B$5:$B$109,"Mondesa Palms") -> 0 | L43: =SUMIFS(Ledger!$C$5:$C$109,Ledger!$F$5:$F$109,$A43,Ledger!$B$5:$B$109,"The Ridge — Rocky Crest Ext 4") -> 0 | M43: =SUMIFS(Ledger!$C$5:$C$109,Ledger!$F$5:$F$109,$A43,Ledger!$B$5:$B$109,"Mango Cove (Otjomuise Ext 10)") -> 0 | N43: =SUMIFS(Ledger!$C$5:$C$109,Ledger!$F$5:$F$109,$A43,Ledger!$B$5:$B$109,"C-Breeze Heights") -> 0 | O43: =SUMIFS(Ledger!$C$5:$C$109,Ledger!$F$5:$F$109,$A43,Ledger!$B$5:$B$109,"Tama Estates") -> 0 | P43: =SUMIFS(Ledger!$C$5:$C$109,Ledger!$F$5:$F$109,$A43,Ledger!$B$5:$B$109,"Duma Tau — Kronlein") -> 451182.19 | Q43: =SUMIFS(Ledger!$C$5:$C$109,Ledger!$F$5:$F$109,$A43,Ledger!$B$5:$B$109,"LIH Nkurenkuru Ph 1") -> 0 | R43: =SUMIFS(Ledger!$C$5:$C$109,Ledger!$F$5:$F$109,$A43,Ledger!$B$5:$B$109,"NIC Otjomuise Ext 10 (Erf 5221)") -> 0 | S43: =SUMIFS(Ledger!$C$5:$C$109,Ledger!$F$5:$F$109,$A43,Ledger!$B$5:$B$109,"Heavens Ark — Otjomuise") -> 0
A44: 45108 | B44: =SUMIFS(Ledger!$D$5:$D$109,Ledger!$F$5:$F$109,$A44) -> 0 | C44: =SUMIFS(Ledger!$E$5:$E$109,Ledger!$F$5:$F$109,$A44) -> 0 | D44: =B44+C44 -> 0 | E44: =D44 -> 0 | F44: =SUMIFS(Ledger!$C$5:$C$109,Ledger!$F$5:$F$109,$A44,Ledger!$B$5:$B$109,"Erf 1470 Khomasdal") -> 0 | G44: =SUMIFS(Ledger!$C$5:$C$109,Ledger!$F$5:$F$109,$A44,Ledger!$B$5:$B$109,"Dunescape Villas (Erf 5159)") -> 0 | H44: =SUMIFS(Ledger!$C$5:$C$109,Ledger!$F$5:$F$109,$A44,Ledger!$B$5:$B$109,"PAM Tree (Erf 5758)") -> 0 | I44: =SUMIFS(Ledger!$C$5:$C$109,Ledger!$F$5:$F$109,$A44,Ledger!$B$5:$B$109,"Turnstone Villas (Erf 8939)") -> 0 | J44: =SUMIFS(Ledger!$C$5:$C$109,Ledger!$F$5:$F$109,$A44,Ledger!$B$5:$B$109,"Lithon Nkurenkuru Ext 2") -> 0 | K44: =SUMIFS(Ledger!$C$5:$C$109,Ledger!$F$5:$F$109,$A44,Ledger!$B$5:$B$109,"Mondesa Palms") -> 0 | L44: =SUMIFS(Ledger!$C$5:$C$109,Ledger!$F$5:$F$109,$A44,Ledger!$B$5:$B$109,"The Ridge — Rocky Crest Ext 4") -> 0 | M44: =SUMIFS(Ledger!$C$5:$C$109,Ledger!$F$5:$F$109,$A44,Ledger!$B$5:$B$109,"Mango Cove (Otjomuise Ext 10)") -> 0 | N44: =SUMIFS(Ledger!$C$5:$C$109,Ledger!$F$5:$F$109,$A44,Ledger!$B$5:$B$109,"C-Breeze Heights") -> 0 | O44: =SUMIFS(Ledger!$C$5:$C$109,Ledger!$F$5:$F$109,$A44,Ledger!$B$5:$B$109,"Tama Estates") -> 0 | P44: =SUMIFS(Ledger!$C$5:$C$109,Ledger!$F$5:$F$109,$A44,Ledger!$B$5:$B$109,"Duma Tau — Kronlein") -> 0 | Q44: =SUMIFS(Ledger!$C$5:$C$109,Ledger!$F$5:$F$109,$A44,Ledger!$B$5:$B$109,"LIH Nkurenkuru Ph 1") -> 0 | R44: =SUMIFS(Ledger!$C$5:$C$109,Ledger!$F$5:$F$109,$A44,Ledger!$B$5:$B$109,"NIC Otjomuise Ext 10 (Erf 5221)") -> 0 | S44: =SUMIFS(Ledger!$C$5:$C$109,Ledger!$F$5:$F$109,$A44,Ledger!$B$5:$B$109,"Heavens Ark — Otjomuise") -> 0
A45: 45139 | B45: =SUMIFS(Ledger!$D$5:$D$109,Ledger!$F$5:$F$109,$A45) -> -6000000 | C45: =SUMIFS(Ledger!$E$5:$E$109,Ledger!$F$5:$F$109,$A45) -> 0 | D45: =B45+C45 -> -6000000 | E45: =D45 -> -6000000 | F45: =SUMIFS(Ledger!$C$5:$C$109,Ledger!$F$5:$F$109,$A45,Ledger!$B$5:$B$109,"Erf 1470 Khomasdal") -> 0 | G45: =SUMIFS(Ledger!$C$5:$C$109,Ledger!$F$5:$F$109,$A45,Ledger!$B$5:$B$109,"Dunescape Villas (Erf 5159)") -> 0 | H45: =SUMIFS(Ledger!$C$5:$C$109,Ledger!$F$5:$F$109,$A45,Ledger!$B$5:$B$109,"PAM Tree (Erf 5758)") -> 0 | I45: =SUMIFS(Ledger!$C$5:$C$109,Ledger!$F$5:$F$109,$A45,Ledger!$B$5:$B$109,"Turnstone Villas (Erf 8939)") -> 0 | J45: =SUMIFS(Ledger!$C$5:$C$109,Ledger!$F$5:$F$109,$A45,Ledger!$B$5:$B$109,"Lithon Nkurenkuru Ext 2") -> 0 | K45: =SUMIFS(Ledger!$C$5:$C$109,Ledger!$F$5:$F$109,$A45,Ledger!$B$5:$B$109,"Mondesa Palms") -> 0 | L45: =SUMIFS(Ledger!$C$5:$C$109,Ledger!$F$5:$F$109,$A45,Ledger!$B$5:$B$109,"The Ridge — Rocky Crest Ext 4") -> 0 | M45: =SUMIFS(Ledger!$C$5:$C$109,Ledger!$F$5:$F$109,$A45,Ledger!$B$5:$B$109,"Mango Cove (Otjomuise Ext 10)") -> 0 | N45: =SUMIFS(Ledger!$C$5:$C$109,Ledger!$F$5:$F$109,$A45,Ledger!$B$5:$B$109,"C-Breeze Heights") -> 0 | O45: =SUMIFS(Ledger!$C$5:$C$109,Ledger!$F$5:$F$109,$A45,Ledger!$B$5:$B$109,"Tama Estates") -> 0 | P45: =SUMIFS(Ledger!$C$5:$C$109,Ledger!$F$5:$F$109,$A45,Ledger!$B$5:$B$109,"Duma Tau — Kronlein") -> 0 | Q45: =SUMIFS(Ledger!$C$5:$C$109,Ledger!$F$5:$F$109,$A45,Ledger!$B$5:$B$109,"LIH Nkurenkuru Ph 1") -> 0 | R45: =SUMIFS(Ledger!$C$5:$C$109,Ledger!$F$5:$F$109,$A45,Ledger!$B$5:$B$109,"NIC Otjomuise Ext 10 (Erf 5221)") -> 0 | S45: =SUMIFS(Ledger!$C$5:$C$109,Ledger!$F$5:$F$109,$A45,Ledger!$B$5:$B$109,"Heavens Ark — Otjomuise") -> 0
